Workbook

Sheet Dashboard
A1: ARNALDO — Modelo financiero 2027–2031 · Dashboard ejecutivo
A2: Proyecto A (marca propia fabricada en Cuba). Condicionado a la confirmación jurídica de la Fase 0. Fecha de corte 10/10/2026.
A4: Escenario activo (cambiar en Assumptions!C4) | B4: =Assumptions!$D$4 -> Base
A6: Indicador | B6: Valor
A7: Unidades vendidas 2031 | B7: =INDEX(Engine!$C$14:$Y$14,1,(Assumptions!$C$4-1)*6+5) -> 6500
A8: Ingresos de la marca 2031 (antes de IEE) | B8: =INDEX(Engine!$C$33:$Y$33,1,(Assumptions!$C$4-1)*6+5) -> 107085.62
A9: EBITDA 2031 | B9: =INDEX(Engine!$C$41:$Y$41,1,(Assumptions!$C$4-1)*6+5) -> -13849.686
A10: EBITDA acumulado 2027–2031 | B10: =SUM(INDEX(Engine!$C$41:$Y$41,1,(Assumptions!$C$4-1)*6+1)+INDEX(Engine!$C$41:$Y$41,1,(Assumptions!$C$4-1)*6+2)+INDEX(Engine!$C$41:$Y$41,1,(Assumptions!$C$4-1)*6+3)+INDEX(Engine!$C$41:$Y$41,1,(Assumptions!$C$4-1)*6+4)+INDEX(Engine!$C$41:$Y$41,1,(Assumptions!$C$4-1)*6+5)) -> -94578.41
A11: Resultado neto acumulado | B11: =INDEX(Engine!$C$54:$Y$54,1,(Assumptions!$C$4-1)*6+1)+INDEX(Engine!$C$54:$Y$54,1,(Assumptions!$C$4-1)*6+2)+INDEX(Engine!$C$54:$Y$54,1,(Assumptions!$C$4-1)*6+3)+INDEX(Engine!$C$54:$Y$54,1,(Assumptions!$C$4-1)*6+4)+INDEX(Engine!$C$54:$Y$54,1,(Assumptions!$C$4-1)*6+5) -> -129034
A12: Necesidad máxima de financiación (capital + deuda) | B12: =INDEX(Scenarios!$B$16:$E$16,1,Assumptions!$C$4) -> 184160.48
A13: Capital aportado (Assumptions) | B13: =Assumptions!$C$9 -> 50000
A14: Financiación ajena máxima requerida | B14: =MAX(INDEX(Engine!$C$75:$Y$75,1,(Assumptions!$C$4-1)*6+1),INDEX(Engine!$C$75:$Y$75,1,(Assumptions!$C$4-1)*6+2),INDEX(Engine!$C$75:$Y$75,1,(Assumptions!$C$4-1)*6+3),INDEX(Engine!$C$75:$Y$75,1,(Assumptions!$C$4-1)*6+4),INDEX(Engine!$C$75:$Y$75,1,(Assumptions!$C$4-1)*6+5)) -> 153816.07
A15: VAN | B15: ='Investment Returns'!B21 -> -120972.97
A16: TIR del proyecto (con valor terminal) | B16: ='Investment Returns'!B22 -> no calculable
A17: Payback | B17: ='Investment Returns'!B24 -> no se recupera en 2027-2031
A18: Punto muerto EBITDA 2030 (unidades/año) | B18: =INDEX(Engine!$C$97:$Y$97,1,(Assumptions!$C$4-1)*6+4) -> 14298.461
A19: Contribución unitaria 2030 (€/u) | B19: =INDEX(Engine!$C$26:$Y$26,1,(Assumptions!$C$4-1)*6+4) -> 1.7477406
A20: Necesidad de caja de un pedido piloto (Working Capital) | B20: ='Working Capital'!$B$38 -> 65779.42
A21: Control de balance (0 = cuadra) | B21: =SUMPRODUCT(ABS(Engine!$C$84:$Y$84)) -> 0
A23: Veredicto financiero automático | B23: =IF(B14>0,"El capital no cubre la necesidad: requiere financiación adicional",IF(B9<=0,"EBITDA 2031 negativo: modelo no sostenible","Autofinanciable con el capital indicado")) -> El capital no cubre la necesidad: requiere financiación adicional
A24: Veredicto jurídico (no calculable) | B24: BLOQUEADO hasta confirmar por escrito la vía legal de fabricación y exportación en Cuba (Fase 0)
A26: Comparativa | B26: Conservador | C26: Base | D26: Optimista | E26: Estrés
A27: Unidades vendidas 2031 | B27: =Scenarios!B6 -> 2500 | C27: =Scenarios!C6 -> 6500 | D27: =Scenarios!D6 -> 12000 | E27: =Scenarios!E6 -> 0
A28: EBITDA 2031 | B28: =Scenarios!B12 -> -35632.408 | C28: =Scenarios!C12 -> -13849.686 | D28: =Scenarios!D12 -> 42857.176 | E28: =Scenarios!E12 -> -29172
A29: EBITDA acumulado 2027–2031 | B29: =Scenarios!B13 -> -161231.04 | C29: =Scenarios!C13 -> -94578.41 | D29: =Scenarios!D13 -> 42913.864 | E29: =Scenarios!E13 -> -154215.78
A30: Necesidad máxima de financiación (capital + deuda) | B30: =Scenarios!B16 -> 209452.12 | C30: =Scenarios!C16 -> 184160.48 | D30: =Scenarios!D16 -> 132822.63 | E30: =Scenarios!E16 -> 172818.08
A31: VAN (tasa de 'Assumptions') | B31: =Scenarios!B18 -> -131046.35 | C31: =Scenarios!C18 -> -120972.97 | D31: =Scenarios!D18 -> 10753.631 | E31: =Scenarios!E18 -> -116081
A32: TIR del proyecto (con valor terminal) | B32: =Scenarios!B19 -> n/c | C32: =Scenarios!C19 -> n/c | D32: =Scenarios!D19 -> 0.21640347 | E32: =Scenarios!E19 -> n/c
A33: Payback (año) | B33: =Scenarios!B20 -> > 2031 | C33: =Scenarios!C20 -> > 2031 | D33: =Scenarios!D20 -> > 2031 | E33: =Scenarios!E20 -> > 2031
A34: Punto muerto EBITDA 2030 (unidades) | B34: =Scenarios!B21 -> n/a | C34: =Scenarios!C21 -> 14298.461 | D34: =Scenarios!D21 -> 4663.7802 | E34: =Scenarios!E21 -> n/a
B36: 2027 | C36: 2028 | D36: 2029 | E36: 2030 | F36: 2031
A37: Serie gráfica: EBITDA escenario activo | B37: =INDEX(Engine!$C$41:$Y$41,1,(Assumptions!$C$4-1)*6+1) -> -27190 | C37: =INDEX(Engine!$C$41:$Y$41,1,(Assumptions!$C$4-1)*6+2) -> -20174.519 | D37: =INDEX(Engine!$C$41:$Y$41,1,(Assumptions!$C$4-1)*6+3) -> -17112.908 | E37: =INDEX(Engine!$C$41:$Y$41,1,(Assumptions!$C$4-1)*6+4) -> -16251.297 | F37: =INDEX(Engine!$C$41:$Y$41,1,(Assumptions!$C$4-1)*6+5) -> -13849.686

Sheet Assumptions
A1: Supuestos del modelo — Proyecto A (marca propia ARNALDO)
A2: Todos los valores en azul son editables. Estados: VERIFICADO / PROBABLE / HIPÓTESIS / BLOQUEADO. Fuentes en 'Sources & Validation'. Fecha de corte: 10/10/2026.
C3: Supuesto editable (input) | D3: Fórmula | E3: Resultado clave | F3: Alerta / bloqueo
A4: Escenario seleccionado (1=Conservador, 2=Base, 3=Optimista, 4=Estrés) | C4: 2 | D4: =INDEX({"Conservador","Base","Optimista","Estrés"},C4) -> Base
A6: 1. Parámetros generales
A7: Parámetro | B7: Unidad | C7: Valor | D7: Estado | E7: Fuente / nota
A8: Primer año del modelo | B8: año | C8: 2027 | D8: HIPÓTESIS | E8: Calendario del promotor
A9: Capital aportado por el promotor (año 1) | B9: € | C9: 50000 | D9: HIPÓTESIS | E9: Comparar 15k–100k en 'Scenarios'
A10: IVA tipo general | B10: % | C10: 0.21 | D10: VERIFICADO | E10: Ley 37/1992
A11: Impuesto especial cigarros: tipo ad valorem sobre PVP | B11: % | C11: 0.158 | D11: VERIFICADO | E11: S14
A12: Impuesto especial cigarros: mínimo | B12: €/1.000 u | C12: 47 | D12: VERIFICADO | E12: S14
A13: Margen del expendedor sobre PVP (cigarros) | B13: % | C13: 0.09 | D13: PROBABLE | E13: S15 (confirmar texto consolidado)
A14: Derecho arancelario UE 2402 10 00 (origen Cuba, sin preferencia) | B14: % CIF | C14: 0.26 | D14: PROBABLE | E14: S32 (confirmar TARIC)
A15: Seguro de transporte | B15: % valor | C15: 0.005 | D15: HIPÓTESIS | E15: Cotizar con transitario
A16: Marcas fiscales + identificador único trazabilidad | B16: €/u | C16: 0.03 | D16: HIPÓTESIS | E16: S27, S28 (coste a confirmar con FNMT/emisor)
A17: Despacho aduanero + agente + inspección por envío | B17: €/envío | C17: 450 | D17: HIPÓTESIS | E17: Cotizar agente de aduanas
A18: Envíos (importaciones) por año con actividad | B18: nº | C18: 2 | D18: HIPÓTESIS | E18: Política de compras
A19: Tipo de cambio USD por EUR | B19: USD/€ | C19: 1.15 | D19: HIPÓTESIS | E19: Si la fábrica cotiza en EUR, poner 1,00
... A24: Cobro al distribuidor | B24: días | C24: 45 | D24: HIPÓTESIS | E24: Negociar con distribuidor habilitado
A25: Pago a proveedores de gastos generales | B25: días | C25: 30 | D25: HIPÓTESIS
A26: IEE pagado al importar (1) o diferido en depósito fiscal (0) | B26: 1/0 | C26: 1 | D26: HIPÓTESIS | E26: Conservador = 1
A27: Fracción anual de IVA pendiente a cierre (liquidación trimestral) | B27: fracción | C27: 0.25 | D27: HIPÓTESIS
A28: Royalty a Arnaldo por nombre/firma (% ingresos de la marca antes de IEE) | B28: % | C28: 0 | D28: HIPÓTESIS | E28: 0% = opción B (sólo equity, recomendada). Opción A: 2% → VAN Optimista −4.561 € y TIR 16,4% (cálculo 10/10/2026)
A29: Participación de Arnaldo en la SL (opción B, con vesting) | B29: % | C29: 0.1 | D29: HIPÓTESIS | E29: Acuerdo con Arnaldo; reparto de valor, no coste
A30: Impuesto sobre Sociedades (España) | B30: % | C30: 0.25 | D30: PROBABLE | E30: N04 (15% nueva creación no aplicado: conservador)
A31: Coste de la financiación ajena (déficit de caja) | B31: % | C31: 0.07 | D31: HIPÓTESIS | E31: Póliza / préstamo socio
A32: Caja mínima operativa | B32: € | C32: 5000 | D32: HIPÓTESIS
A33: Vida útil intangibles (marca, diseño) | B33: años | C33: 5 | D33: HIPÓTESIS
A34: Tasa de descuento (riesgo alto, no cotizada) | B34: % | C34: 0.18 | D34: HIPÓTESIS | E34: Prima por riesgo país/regulatorio
A35: Múltiplo EV/EBITDA en 2031 (valor terminal) | B35: x | C35: 5 | D35: HIPÓTESIS | E35: Conservador para marca pequeña
A37: 2. Parámetros por escenario
A38: Parámetro | B38: Unidad | C38: Conservador | D38: Base | E38: Optimista | F38: Estrés | G38: Seleccionado | H38: Estado | I38: Fuente / nota
A39: PVP por unidad (IVA e IEE incluidos) | B39: €/u | C39: 20 | D39: 24 | E39: 28 | F39: 24 | G39: =INDEX(C39:F39,Assumptions!$C$4) -> 24 | H39: HIPÓTESIS | I39: Benchmarks S37/S38: Partagás D4 ≈21,20 €; Montecristo No.2 21,80 €; Davidoff Puro Dominicano 15,50 €. Ver rejilla 12–35 € en Unit Economics
A40: Precio de fabricación FOB/FCA por unidad (sin cotización) | B40: USD/u | C40: 7 | D40: 6 | E40: 5 | F40: 7.5 | G40: =INDEX(C40:F40,Assumptions!$C$4) -> 6 | H40: BLOQUEADO | I40: Requiere cotización formal del fabricante/exportador
A41: Factor sobre coste de packaging base ('Product Cost') | B41: x | C41: 1.1 | D41: 1 | E41: 0.9 | F41: 1.2 | G41: =INDEX(C41:F41,Assumptions!$C$4) -> 1 | H41: HIPÓTESIS
A42: Control de calidad en origen (inspección, catas, laboratorio) | B42: €/u | C42: 0.3 | D42: 0.25 | E42: 0.2 | F42: 0.35 | G42: =INDEX(C42:F42,Assumptions!$C$4) -> 0.25 | H42: HIPÓTESIS
A43: Flete internacional + manipulación hasta almacén | B43: €/u | C43: 0.7 | D43: 0.55 | E43: 0.4 | F43: 0.9 | G43: =INDEX(C43:F43,Assumptions!$C$4) -> 0.55 | H43: HIPÓTESIS | I43: Aéreo en lotes pequeños
A44: Honorario técnico de Arnaldo (pagado vía entidad autorizada) | B44: €/u | C44: 0.4 | D44: 0.35 | E44: 0.3 | F44: 0.4 | G44: =INDEX(C44:F44,Assumptions!$C$4) -> 0.35 | H44: BLOQUEADO | I44: Forma legal de pago sin confirmar
A45: Tarifa del distribuidor mayorista habilitado | B45: % PVP | C45: 0.06 | D45: 0.05 | E45: 0.045 | F45: 0.06 | G45: =INDEX(C45:F45,Assumptions!$C$4) -> 0.05 | H45: HIPÓTESIS | I45: Negociable; no regulada
A46: Merma y rechazos post-importación | B46: % compras | C46: 0.05 | D46: 0.03 | E46: 0.02 | F46: 0.08 | G46: =INDEX(C46:F46,Assumptions!$C$4) -> 0.03 | H46: HIPÓTESIS
...

Sheet Product Cost
A1: Coste de producto — desglose de packaging y coste en destino
A2: Packaging base por unidad (escenario Base). Los escenarios aplican el factor de 'Assumptions'. Todos los importes sin IVA.
A4: Componente (caja de 10 u) | B4: Unidad | C4: Coste por caja (€) | D4: Coste por unidad (€) | E4: Estado | F4: Nota
A5: Caja de cedro español macizo con bisagra y cierre | B5: caja | C5: 11.5 | D5: =C5/Assumptions!$C$20 -> 1.15 | E5: HIPÓTESIS | F5: Cotizar en Cuba (fabricación local) y en España
A6: Anilla principal (papel algodón, stamping oro, relieve) | B6: caja | C6: 1.2 | D6: =C6/Assumptions!$C$20 -> 0.12 | E6: HIPÓTESIS | F6: 0,12 €/u en tiradas ≥10.000
A7: Pie de anilla / numeración de pliego | B7: caja | C7: 0.4 | D7: =C7/Assumptions!$C$20 -> 0.04 | E7: HIPÓTESIS
A8: Hoja de cedro interior + papel de seda | B8: caja | C8: 0.6 | D8: =C8/Assumptions!$C$20 -> 0.06 | E8: HIPÓTESIS
A9: Colofón impreso numerado (tarjeta interior) | B9: caja | C9: 0.8 | D9: =C9/Assumptions!$C$20 -> 0.08 | E9: HIPÓTESIS | F9: Elemento de trazabilidad de lote
A10: Etiquetado de advertencias sanitarias (laterales/tapa) | B10: caja | C10: 0.7 | D10: =C10/Assumptions!$C$20 -> 0.07 | E10: HIPÓTESIS | F10: Diseño conforme RD 579/2017
A11: Precinto de garantía de la marca (no fiscal) | B11: caja | C11: 0.5 | D11: =C11/Assumptions!$C$20 -> 0.05 | E11: HIPÓTESIS | F11: No imita sellos de Habanos
A12: Retractilado + cartón exterior de expedición (prorrata) | B12: caja | C12: 0.8 | D12: =C12/Assumptions!$C$20 -> 0.08 | E12: HIPÓTESIS
A13: TOTAL packaging base | C13: =SUM(C5:C12) -> 16.5 | D13: =SUM(D5:D12) -> 1.65
A15: Coste en destino por unidad — escenario seleccionado (lee del motor)
A16: Concepto (€/u) | B16: 2027 | C16: 2028 | D16: 2029 | E16: 2030 | F16: 2031
A17: Fabricación FOB (€) | B17: =INDEX(Engine!$C$20:$Y$20,1,(Assumptions!$C$4-1)*6+1) -> 5.2173913 | C17: =INDEX(Engine!$C$20:$Y$20,1,(Assumptions!$C$4-1)*6+2) -> 5.2173913 | D17: =INDEX(Engine!$C$20:$Y$20,1,(Assumptions!$C$4-1)*6+3) -> 5.2173913 | E17: =INDEX(Engine!$C$20:$Y$20,1,(Assumptions!$C$4-1)*6+4) -> 5.2173913 | F17: =INDEX(Engine!$C$20:$Y$20,1,(Assumptions!$C$4-1)*6+5) -> 5.2173913
A18: Packaging | B18: =INDEX(Engine!$C$21:$Y$21,1,(Assumptions!$C$4-1)*6+1) -> 1.65 | C18: =INDEX(Engine!$C$21:$Y$21,1,(Assumptions!$C$4-1)*6+2) -> 1.65 | D18: =INDEX(Engine!$C$21:$Y$21,1,(Assumptions!$C$4-1)*6+3) -> 1.65 | E18: =INDEX(Engine!$C$21:$Y$21,1,(Assumptions!$C$4-1)*6+4) -> 1.65 | F18: =INDEX(Engine!$C$21:$Y$21,1,(Assumptions!$C$4-1)*6+5) -> 1.65
A19: Valor CIF (incl. QC, flete, seguro) | B19: =INDEX(Engine!$C$22:$Y$22,1,(Assumptions!$C$4-1)*6+1) -> 7.7057283 | C19: =INDEX(Engine!$C$22:$Y$22,1,(Assumptions!$C$4-1)*6+2) -> 7.7057283 | D19: =INDEX(Engine!$C$22:$Y$22,1,(Assumptions!$C$4-1)*6+3) -> 7.7057283 | E19: =INDEX(Engine!$C$22:$Y$22,1,(Assumptions!$C$4-1)*6+4) -> 7.7057283 | F19: =INDEX(Engine!$C$22:$Y$22,1,(Assumptions!$C$4-1)*6+5) -> 7.7057283
A20: Arancel | B20: =INDEX(Engine!$C$23:$Y$23,1,(Assumptions!$C$4-1)*6+1) -> 2.0034893 | C20: =INDEX(Engine!$C$23:$Y$23,1,(Assumptions!$C$4-1)*6+2) -> 2.0034893 | D20: =INDEX(Engine!$C$23:$Y$23,1,(Assumptions!$C$4-1)*6+3) -> 2.0034893 | E20: =INDEX(Engine!$C$23:$Y$23,1,(Assumptions!$C$4-1)*6+4) -> 2.0034893 | F20: =INDEX(Engine!$C$23:$Y$23,1,(Assumptions!$C$4-1)*6+5) -> 2.0034893
A21: Coste en destino (incl. marcas fiscales y honorario técnico) | B21: =INDEX(Engine!$C$24:$Y$24,1,(Assumptions!$C$4-1)*6+1) -> 10.089218 | C21: =INDEX(Engine!$C$24:$Y$24,1,(Assumptions!$C$4-1)*6+2) -> 10.089218 | D21: =INDEX(Engine!$C$24:$Y$24,1,(Assumptions!$C$4-1)*6+3) -> 10.089218 | E21: =INDEX(Engine!$C$24:$Y$24,1,(Assumptions!$C$4-1)*6+4) -> 10.089218 | F21: =INDEX(Engine!$C$24:$Y$24,1,(Assumptions!$C$4-1)*6+5) -> 10.089218
A22: Impuesto especial por unidad | B22: =INDEX(Engine!$C$25:$Y$25,1,(Assumptions!$C$4-1)*6+1) -> 3.792 | C22: =INDEX(Engine!$C$25:$Y$25,1,(Assumptions!$C$4-1)*6+2) -> 3.792 | D22: =INDEX(Engine!$C$25:$Y$25,1,(Assumptions!$C$4-1)*6+3) -> 3.792 | E22: =INDEX(Engine!$C$25:$Y$25,1,(Assumptions!$C$4-1)*6+4) -> 3.792 | F22: =INDEX(Engine!$C$25:$Y$25,1,(Assumptions!$C$4-1)*6+5) -> 3.792
A23: Contribución por unidad vendida | B23: =INDEX(Engine!$C$26:$Y$26,1,(Assumptions!$C$4-1)*6+1) -> 1.7477406 | C23: =INDEX(Engine!$C$26:$Y$26,1,(Assumptions!$C$4-1)*6+2) -> 1.7477406 | D23: =INDEX(Engine!$C$26:$Y$26,1,(Assumptions!$C$4-1)*6+3) -> 1.7477406 | E23: =INDEX(Engine!$C$26:$Y$26,1,(Assumptions!$C$4-1)*6+4) -> 1.7477406 | F23: =INDEX(Engine!$C$26:$Y$26,1,(Assumptions!$C$4-1)*6+5) -> 1.7477406
A25: Coste en destino por caja de 10 (2028) | C25: =C21*Assumptions!$C$20 -> 100.89218

Sheet Import & Taxes
A1: Importación y fiscalidad — simulación de un envío (DUA) y reparto del PVP
A2: Escenario seleccionado. El IVA de importación es recuperable (impacto de caja, no de coste). Base IVA importación = valor en aduana + arancel + IEE.
A4: Unidades del envío | C4: 3000
A5: Valor en aduana (CIF) por unidad | C5: =INDEX(Engine!$C$22:$Y$22,1,(Assumptions!$C$4-1)*6+2) -> 7.7057283
A6: Valor en aduana del envío | C6: =C4*C5 -> 23117.185
A7: Derecho arancelario | C7: =C6*Assumptions!$C$14 -> 6010.468
A8: Impuesto especial (si se paga al importar) | C8: =C4*INDEX(Engine!$C$25:$Y$25,1,(Assumptions!$C$4-1)*6+2)*Assumptions!$C$26 -> 11376
A9: Base imponible IVA importación | C9: =C6+C7+C8 -> 40503.653
A10: IVA de importación (recuperable) | C10: =C9*Assumptions!$C$10 -> 8505.7671
A11: Despacho y agente de aduanas | C11: =Assumptions!$C$17 -> 450
A12: PAGO TOTAL EN FRONTERA | C12: =C7+C8+C10+C11 -> 26342.235
A13: de ello, coste definitivo (arancel + despacho) | C13: =C7+C11 -> 6460.468
A14: de ello, impuesto recuperable vía precio de venta (IEE) | C14: =C8 -> 11376
A15: de ello, IVA recuperable vía liquidación (≈1 trimestre) | C15: =C10 -> 8505.7671
A17: Reparto del PVP de una unidad (año 2028, escenario seleccionado)
A18: Destino del PVP | C18: €/u | D18: % PVP
A19: IVA (Hacienda) | C19: =INDEX(Engine!$C$19:$Y$19,1,(Assumptions!$C$4-1)*6+2)*Assumptions!$C$10/(1+Assumptions!$C$10) -> 4.1652893 | D19: =C19/INDEX(Engine!$C$19:$Y$19,1,(Assumptions!$C$4-1)*6+2) -> 0.17355372
A20: Impuesto especial (Hacienda) | C20: =INDEX(Engine!$C$25:$Y$25,1,(Assumptions!$C$4-1)*6+2) -> 3.792 | D20: =C20/INDEX(Engine!$C$19:$Y$19,1,(Assumptions!$C$4-1)*6+2) -> 0.158
A21: Margen expendedor | C21: =INDEX(Engine!$C$19:$Y$19,1,(Assumptions!$C$4-1)*6+2)*Assumptions!$C$13 -> 2.16 | D21: =C21/INDEX(Engine!$C$19:$Y$19,1,(Assumptions!$C$4-1)*6+2) -> 0.09
A22: Tarifa distribuidor | C22: =INDEX(Engine!$C$19:$Y$19,1,(Assumptions!$C$4-1)*6+2)*Assumptions!$G$45 -> 1.2 | D22: =C22/INDEX(Engine!$C$19:$Y$19,1,(Assumptions!$C$4-1)*6+2) -> 0.05
A23: Arancel (Hacienda UE) | C23: =INDEX(Engine!$C$23:$Y$23,1,(Assumptions!$C$4-1)*6+2) -> 2.0034893 | D23: =C23/INDEX(Engine!$C$19:$Y$19,1,(Assumptions!$C$4-1)*6+2) -> 0.083478723
A24: Fabricación, packaging, QC, flete, seguro | C24: =INDEX(Engine!$C$22:$Y$22,1,(Assumptions!$C$4-1)*6+2) -> 7.7057283 | D24: =C24/INDEX(Engine!$C$19:$Y$19,1,(Assumptions!$C$4-1)*6+2) -> 0.32107201
A25: Marcas fiscales + honorario técnico | C25: =INDEX(Engine!$C$24:$Y$24,1,(Assumptions!$C$4-1)*6+2)-INDEX(Engine!$C$22:$Y$22,1,(Assumptions!$C$4-1)*6+2)-INDEX(Engine!$C$23:$Y$23,1,(Assumptions!$C$4-1)*6+2) -> 0.38 | D25: =C25/INDEX(Engine!$C$19:$Y$19,1,(Assumptions!$C$4-1)*6+2) -> 0.015833333
A26: Merma y muestras (coste + IEE) | C26: =(INDEX(Engine!$C$10:$Y$10,1,(Assumptions!$C$4-1)*6+2)-1)*(INDEX(Engine!$C$25:$Y$25,1,(Assumptions!$C$4-1)*6+2)+INDEX(Engine!$C$24:$Y$24,1,(Assumptions!$C$4-1)*6+2)) -> 0.84575254 | D26: =C26/INDEX(Engine!$C$19:$Y$19,1,(Assumptions!$C$4-1)*6+2) -> 0.035239689
A27: Royalty de nombre a Arnaldo | C27: =(INDEX(Engine!$C$19:$Y$19,1,(Assumptions!$C$4-1)*6+2)/(1+Assumptions!$C$10)-INDEX(Engine!$C$19:$Y$19,1,(Assumptions!$C$4-1)*6+2)*(Assumptions!$C$13+Assumptions!$G$45))*Assumptions!$C$28 -> 0 | D27: =C27/INDEX(Engine!$C$19:$Y$19,1,(Assumptions!$C$4-1)*6+2) -> 0
A28: Contribución de la marca (antes de gastos fijos) | C28: =INDEX(Engine!$C$26:$Y$26,1,(Assumptions!$C$4-1)*6+2) -> 1.7477406 | D28: =C28/INDEX(Engine!$C$19:$Y$19,1,(Assumptions!$C$4-1)*6+2) -> 0.072822525
A29: Control: suma = PVP | C29: =SUM(C19:C28) -> 24 | D29: =SUM(D19:D28) -> 1

Sheet Unit Economics
A1: Economía unitaria por nivel de PVP (costes del escenario seleccionado, año 2028)
A2: Cada columna recalcula impuestos y márgenes para el PVP indicado. Las cifras del distribuidor, expendedor y marca se separan explícitamente.
A4: Concepto (€/u) | B4: PVP 12 € | C4: PVP 15 € | D4: PVP 18 € | E4: PVP 20 € | F4: PVP 25 € | G4: PVP 30 € | H4: PVP 35 €
A5: PVP (input) | B5: 12 | C5: 15 | D5: 18 | E5: 20 | F5: 25 | G5: 30 | H5: 35
A6: IVA incluido en PVP | B6: =B5*Assumptions!$C$10/(1+Assumptions!$C$10) -> 2.0826446 | C6: =C5*Assumptions!$C$10/(1+Assumptions!$C$10) -> 2.6033058 | D6: =D5*Assumptions!$C$10/(1+Assumptions!$C$10) -> 3.1239669 | E6: =E5*Assumptions!$C$10/(1+Assumptions!$C$10) -> 3.4710744 | F6: =F5*Assumptions!$C$10/(1+Assumptions!$C$10) -> 4.338843 | G6: =G5*Assumptions!$C$10/(1+Assumptions!$C$10) -> 5.2066116 | H6: =H5*Assumptions!$C$10/(1+Assumptions!$C$10) -> 6.0743802
A7: Impuesto especial (15,8% PVP, mín. 0,047 €) | B7: =MAX(Assumptions!$C$11*B5,Assumptions!$C$12/1000) -> 1.896 | C7: =MAX(Assumptions!$C$11*C5,Assumptions!$C$12/1000) -> 2.37 | D7: =MAX(Assumptions!$C$11*D5,Assumptions!$C$12/1000) -> 2.844 | E7: =MAX(Assumptions!$C$11*E5,Assumptions!$C$12/1000) -> 3.16 | F7: =MAX(Assumptions!$C$11*F5,Assumptions!$C$12/1000) -> 3.95 | G7: =MAX(Assumptions!$C$11*G5,Assumptions!$C$12/1000) -> 4.74 | H7: =MAX(Assumptions!$C$11*H5,Assumptions!$C$12/1000) -> 5.53
A8: Margen expendedor | B8: =B5*Assumptions!$C$13 -> 1.08 | C8: =C5*Assumptions!$C$13 -> 1.35 | D8: =D5*Assumptions!$C$13 -> 1.62 | E8: =E5*Assumptions!$C$13 -> 1.8 | F8: =F5*Assumptions!$C$13 -> 2.25 | G8: =G5*Assumptions!$C$13 -> 2.7 | H8: =H5*Assumptions!$C$13 -> 3.15
A9: Tarifa distribuidor | B9: =B5*Assumptions!$G$45 -> 0.6 | C9: =C5*Assumptions!$G$45 -> 0.75 | D9: =D5*Assumptions!$G$45 -> 0.9 | E9: =E5*Assumptions!$G$45 -> 1 | F9: =F5*Assumptions!$G$45 -> 1.25 | G9: =G5*Assumptions!$G$45 -> 1.5 | H9: =H5*Assumptions!$G$45 -> 1.75
A10: Ingreso de la marca antes de IEE | B10: =B5/(1+Assumptions!$C$10)-B8-B9 -> 8.2373554 | C10: =C5/(1+Assumptions!$C$10)-C8-C9 -> 10.296694 | D10: =D5/(1+Assumptions!$C$10)-D8-D9 -> 12.356033 | E10: =E5/(1+Assumptions!$C$10)-E8-E9 -> 13.728926 | F10: =F5/(1+Assumptions!$C$10)-F8-F9 -> 17.161157 | G10: =G5/(1+Assumptions!$C$10)-G8-G9 -> 20.593388 | H10: =H5/(1+Assumptions!$C$10)-H8-H9 -> 24.02562
A11: Ingreso de la marca neto de IEE | B11: =B10-B7 -> 6.3413554 | C11: =C10-C7 -> 7.9266942 | D11: =D10-D7 -> 9.5120331 | E11: =E10-E7 -> 10.568926 | F11: =F10-F7 -> 13.211157 | G11: =G10-G7 -> 15.853388 | H11: =H10-H7 -> 18.49562
A12: Coste en destino (sin IEE) | B12: =INDEX(Engine!$C$24:$Y$24,1,(Assumptions!$C$4-1)*6+2) -> 10.089218 | C12: =INDEX(Engine!$C$24:$Y$24,1,(Assumptions!$C$4-1)*6+2) -> 10.089218 | D12: =INDEX(Engine!$C$24:$Y$24,1,(Assumptions!$C$4-1)*6+2) -> 10.089218 | E12: =INDEX(Engine!$C$24:$Y$24,1,(Assumptions!$C$4-1)*6+2) -> 10.089218 | F12: =INDEX(Engine!$C$24:$Y$24,1,(Assumptions!$C$4-1)*6+2) -> 10.089218 | G12: =INDEX(Engine!$C$24:$Y$24,1,(Assumptions!$C$4-1)*6+2) -> 10.089218 | H12: =INDEX(Engine!$C$24:$Y$24,1,(Assumptions!$C$4-1)*6+2) -> 10.089218
A13: Merma y muestras (coste + IEE) | B13: =(INDEX(Engine!$C$10:$Y$10,1,(Assumptions!$C$4-1)*6+2)-1)*(B7+B12) -> 0.73023336 | C13: =(INDEX(Engine!$C$10:$Y$10,1,(Assumptions!$C$4-1)*6+2)-1)*(C7+C12) -> 0.75911316 | D13: =(INDEX(Engine!$C$10:$Y$10,1,(Assumptions!$C$4-1)*6+2)-1)*(D7+D12) -> 0.78799295 | E13: =(INDEX(Engine!$C$10:$Y$10,1,(Assumptions!$C$4-1)*6+2)-1)*(E7+E12) -> 0.80724615 | F13: =(INDEX(Engine!$C$10:$Y$10,1,(Assumptions!$C$4-1)*6+2)-1)*(F7+F12) -> 0.85537913 | G13: =(INDEX(Engine!$C$10:$Y$10,1,(Assumptions!$C$4-1)*6+2)-1)*(G7+G12) -> 0.90351212 | H13: =(INDEX(Engine!$C$10:$Y$10,1,(Assumptions!$C$4-1)*6+2)-1)*(H7+H12) -> 0.95164511
A14: CONTRIBUCIÓN por unidad (tras royalty Arnaldo) | B14: =B11-B12-B13-B10*Assumptions!$C$28 -> -4.4780956 | C14: =C11-C12-C13-C10*Assumptions!$C$28 -> -2.9216365 | D14: =D11-D12-D13-D10*Assumptions!$C$28 -> -1.3651775 | E14: =E11-E12-E13-E10*Assumptions!$C$28 -> -0.32753813 | F14: =F11-F12-F13-F10*Assumptions!$C$28 -> 2.2665603 | G14: =G11-G12-G13-G10*Assumptions!$C$28 -> 4.8606587 | H14: =H11-H12-H13-H10*Assumptions!$C$28 -> 7.4547571
A15: Margen de contribución sobre ingreso neto de IEE | B15: =IF(B11<>0,B14/B11,0) -> -0.70617326 | C15: =IF(C11<>0,C14/C11,0) -> -0.36858197 | D15: =IF(D11<>0,D14/D11,0) -> -0.14352111 | E15: =IF(E11<>0,E14/E11,0) -> -0.030990675 | F15: =IF(F11<>0,F14/F11,0) -> 0.1715641 | G15: =IF(G11<>0,G14/G11,0) -> 0.30660062 | H15: =IF(H11<>0,H14/H11,0) -> 0.40305527
A16: Contribución sobre PVP | B16: =B14/B5 -> -0.37317463 | C16: =C14/C5 -> -0.19477577 | D16: =D14/D5 -> -0.075843194 | E16: =E14/E5 -> -0.016376907 | F16: =F14/F5 -> 0.090662411 | G16: =G14/G5 -> 0.16202196 | H16: =H14/H5 -> 0.21299306
A17: Punto muerto EBITDA 2030 (unidades/año) | B17: =IF(B14>0,(INDEX(Engine!$C$40:$Y$40,1,(Assumptions!$C$4-1)*6+4)+Assumptions!$C$18*Assumptions!$C$17)/B14,"no viable") -> no viable | C17: =IF(C14>0,(INDEX(Engine!$C$40:$Y$40,1,(Assumptions!$C$4-1)*6+4)+Assumptions!$C$18*Assumptions!$C$17)/C14,"no viable") -> no viable | D17: =IF(D14>0,(INDEX(Engine!$C$40:$Y$40,1,(Assumptions!$C$4-1)*6+4)+Assumptions!$C$18*Assumptions!$C$17)/D14,"no viable") -> no viable | E17: =IF(E14>0,(INDEX(Engine!$C$40:$Y$40,1,(Assumptions!$C$4-1)*6+4)+Assumptions!$C$18*Assumptions!$C$17)/E14,"no viable") -> no viable | F17: =IF(F14>0,(INDEX(Engine!$C$40:$Y$40,1,(Assumptions!$C$4-1)*6+4)+Assumptions!$C$18*Assumptions!$C$17)/F14,"no viable") -> 11025.517 | G17: =IF(G14>0,(INDEX(Engine!$C$40:$Y$40,1,(Assumptions!$C$4-1)*6+4)+Assumptions!$C$18*Assumptions!$C$17)/G14,"no viable") -> 5141.2785 | H17: =IF(H14>0,(INDEX(Engine!$C$40:$Y$40,1,(Assumptions!$C$4-1)*6+4)+Assumptions!$C$18*Assumptions!$C$17)/H14,"no viable") -> 3352.2219
A18: FOB máximo (USD) para contribución ≥ 25% del ingreso neto | B18: =MAX(0,((B11*0.75-B10*Assumptions!$C$28-B7*(INDEX(Engine!$C$10:$Y$10,1,(Assumptions!$C$4-1)*6+2)-1))/INDEX(Engine!$C$10:$Y$10,1,(Assumptions!$C$4-1)*6+2)-(INDEX(Engine!$C$24:$Y$24,1,(Assumptions!$C$4-1)*6+2)-INDEX(Engine!$C$20:$Y$20,1,(Assumptions!$C$4-1)*6+2)*(1+Assumptions!$C$15)*(1+Assumptions!$C$14)))/((1+Assumptions!$C$15)*(1+Assumptions!$C$14))*Assumptions!$C$19) -> 0.8096807 | C18: =MAX(0,((C11*0.75-C10*Assumptions!$C$28-C7*(INDEX(Engine!$C$10:$Y$10,1,(Assumptions!$C$4-1)*6+2)-1))/INDEX(Engine!$C$10:$Y$10,1,(Assumptions!$C$4-1)*6+2)-(INDEX(Engine!$C$24:$Y$24,1,(Assumptions!$C$4-1)*6+2)-INDEX(Engine!$C$20:$Y$20,1,(Assumptions!$C$4-1)*6+2)*(1+Assumptions!$C$15)*(1+Assumptions!$C$14)))/((1+Assumptions!$C$15)*(1+Assumptions!$C$14))*Assumptions!$C$19) -> 1.8027508 | D18: =MAX(0,((D11*0.75-D10*Assumptions!$C$28-D7*(INDEX(Engine!$C$10:$Y$10,1,(Assumptions!$C$4-1)*6+2)-1))/INDEX(Engine!$C$10:$Y$10,1,(Assumptions!$C$4-1)*6+2)-(INDEX(Engine!$C$24:$Y$24,1,(Assumptions!$C$4-1)*6+2)-INDEX(Engine!$C$20:$Y$20,1,(Assumptions!$C$4-1)*6+2)*(1+Assumptions!$C$15)*(1+Assumptions!$C$14)))/((1+Assumptions!$C$15)*(1+Assumptions!$C$14))*Assumptions!$C$19) -> 2.795821 | E18: =MAX(0,((E11*0.75-E10*Assumptions!$C$28-E7*(INDEX(Engine!$C$10:$Y$10,1,(Assumptions!$C$4-1)*6+2)-1))/INDEX(Engine!$C$10:$Y$10,1,(Assumptions!$C$4-1)*6+2)-(INDEX(Engine!$C$24:$Y$24,1,(Assumptions!$C$4-1)*6+2)-INDEX(Engine!$C$20:$Y$20,1,(Assumptions!$C$4-1)*6+2)*(1+Assumptions!$C$15)*(1+Assumptions!$C$14)))/((1+Assumptions!$C$15)*(1+Assumptions!$C$14))*Assumptions!$C$19) -> 3.4578678 | F18: =MAX(0,((F11*0.75-F10*Assumptions!$C$28-F7*(INDEX(Engine!$C$10:$Y$10,1,(Assumptions!$C$4-1)*6+2)-1))/INDEX(Engine!$C$10:$Y$10,1,(Assumptions!$C$4-1)*6+2)-(INDEX(Engine!$C$24:$Y$24,1,(Assumptions!$C$4-1)*6+2)-INDEX(Engine!$C$20:$Y$20,1,(Assumptions!$C$4-1)*6+2)*(1+Assumptions!$C$15)*(1+Assumptions!$C$14)))/((1+Assumptions!$C$15)*(1+Assumptions!$C$14))*Assumptions!$C$19) -> 5.1129847 | G18: =MAX(0,((G11*0.75-G10*Assumptions!$C$28-G7*(INDEX(Engine!$C$10:$Y$10,1,(Assumptions!$C$4-1)*6+2)-1))/INDEX(Engine!$C$10:$Y$10,1,(Assumptions!$C$4-1)*6+2)-(INDEX(Engine!$C$24:$Y$24,1,(Assumptions!$C$4-1)*6+2)-INDEX(Engine!$C$20:$Y$20,1,(Assumptions!$C$4-1)*6+2)*(1+Assumptions!$C$15)*(1+Assumptions!$C$14)))/((1+Assumptions!$C$15)*(1+Assumptions!$C$14))*Assumptions!$C$19) -> 6.7681016 | H18: =MAX(0,((H11*0.75-H10*Assumptions!$C$28-H7*(INDEX(Engine!$C$10:$Y$10,1,(Assumptions!$C$4-1)*6+2)-1))/INDEX(Engine!$C$10:$Y$10,1,(Assumptions!$C$4-1)*6+2)-(INDEX(Engine!$C$24:$Y$24,1,(Assumptions!$C$4-1)*6+2)-INDEX(Engine!$C$20:$Y$20,1,(Assumptions!$C$4-1)*6+2)*(1+Assumptions!$C$15)*(1+Assumptions!$C$14)))/((1+Assumptions!$C$15)*(1+Assumptions!$C$14))*Assumptions!$C$19) -> 8.4232185
A21: Lectura: el Estado (IVA+IEE+arancel) captura ~35-40% del PVP; el canal (expendedor+distribuidor) ~14%. La marca debe pagar fábrica, logística y estructura con el resto.

Sheet Sales Forecast
A1: Previsión de demanda (unidades) por escenario
A2: Demanda B2B a través del canal legal (distribuidor habilitado → expendedurías). 2027 = año de habilitaciones, sin ventas.
A4: Escenario | B4: 2027 | C4: 2028 | D4: 2029 | E4: 2030 | F4: 2031 | G4: Total
A5: Conservador | B5: 0 | C5: 1000 | D5: 1500 | E5: 2000 | F5: 2500 | G5: =SUM(B5:F5) -> 7000
A6: Base | B6: 0 | C6: 2000 | D6: 3500 | E6: 5000 | F6: 6500 | G6: =SUM(B6:F6) -> 17000
A7: Optimista | B7: 0 | C7: 3500 | D7: 6000 | E7: 9000 | F7: 12000 | G7: =SUM(B7:F7) -> 30500
A8: Estrés (demanda; suministro bloqueado desde 2029) | B8: 0 | C8: 2000 | D8: 3500 | E8: 5000 | F8: 6500 | G8: =SUM(B8:F8) -> 17000
A11: Escenario seleccionado — volumen derivado y esfuerzo comercial
A12: Concepto | B12: 2027 | C12: 2028 | D12: 2029 | E12: 2030 | F12: 2031
A13: Unidades vendidas | B13: =INDEX(Engine!$C$14:$Y$14,1,(Assumptions!$C$4-1)*6+1) -> 0 | C13: =INDEX(Engine!$C$14:$Y$14,1,(Assumptions!$C$4-1)*6+2) -> 2000 | D13: =INDEX(Engine!$C$14:$Y$14,1,(Assumptions!$C$4-1)*6+3) -> 3500 | E13: =INDEX(Engine!$C$14:$Y$14,1,(Assumptions!$C$4-1)*6+4) -> 5000 | F13: =INDEX(Engine!$C$14:$Y$14,1,(Assumptions!$C$4-1)*6+5) -> 6500
A14: Unidades importadas | B14: =INDEX(Engine!$C$13:$Y$13,1,(Assumptions!$C$4-1)*6+1) -> 1000 | C14: =INDEX(Engine!$C$13:$Y$13,1,(Assumptions!$C$4-1)*6+2) -> 2871.8557 | D14: =INDEX(Engine!$C$13:$Y$13,1,(Assumptions!$C$4-1)*6+3) -> 4463.2474 | E14: =INDEX(Engine!$C$13:$Y$13,1,(Assumptions!$C$4-1)*6+4) -> 6054.6392 | F14: =INDEX(Engine!$C$13:$Y$13,1,(Assumptions!$C$4-1)*6+5) -> 6896.0309
A15: Stock final (unidades) | B15: =INDEX(Engine!$C$16:$Y$16,1,(Assumptions!$C$4-1)*6+1) -> 1000 | C15: =INDEX(Engine!$C$16:$Y$16,1,(Assumptions!$C$4-1)*6+2) -> 1750 | D15: =INDEX(Engine!$C$16:$Y$16,1,(Assumptions!$C$4-1)*6+3) -> 2500 | E15: =INDEX(Engine!$C$16:$Y$16,1,(Assumptions!$C$4-1)*6+4) -> 3250 | F15: =INDEX(Engine!$C$16:$Y$16,1,(Assumptions!$C$4-1)*6+5) -> 3250
A16: Cajas vendidas | B16: =B13/Assumptions!$C$20 -> 0 | C16: =C13/Assumptions!$C$20 -> 200 | D16: =D13/Assumptions!$C$20 -> 350 | E16: =E13/Assumptions!$C$20 -> 500 | F16: =F13/Assumptions!$C$20 -> 650
A17: Puntos de venta activos necesarios | B17: =INDEX(Engine!$C$99:$Y$99,1,(Assumptions!$C$4-1)*6+1) -> 0 | C17: =INDEX(Engine!$C$99:$Y$99,1,(Assumptions!$C$4-1)*6+2) -> 50 | D17: =INDEX(Engine!$C$99:$Y$99,1,(Assumptions!$C$4-1)*6+3) -> 87.5 | E17: =INDEX(Engine!$C$99:$Y$99,1,(Assumptions!$C$4-1)*6+4) -> 125 | F17: =INDEX(Engine!$C$99:$Y$99,1,(Assumptions!$C$4-1)*6+5) -> 162.5
A18: Ventas a PVP (consumidor) | B18: =INDEX(Engine!$C$29:$Y$29,1,(Assumptions!$C$4-1)*6+1) -> 0 | C18: =INDEX(Engine!$C$29:$Y$29,1,(Assumptions!$C$4-1)*6+2) -> 48000 | D18: =INDEX(Engine!$C$29:$Y$29,1,(Assumptions!$C$4-1)*6+3) -> 84000 | E18: =INDEX(Engine!$C$29:$Y$29,1,(Assumptions!$C$4-1)*6+4) -> 120000 | F18: =INDEX(Engine!$C$29:$Y$29,1,(Assumptions!$C$4-1)*6+5) -> 156000

Sheet Operating Expenses
A1: Gastos operativos fijos y CAPEX (escenario Base, € sin IVA)
A2: El motor multiplica el total por el factor de escenario. 'Remuneración del promotor' = 0: el modelo muestra el resultado ANTES de retribuir al gestor.
A4: Partida | B4: Estado | C4: 2027 | D4: 2028 | E4: 2029 | F4: 2030 | G4: 2031
A5: Due diligence jurídica Cuba (Fase 0) — abogado cubano + español | B5: HIPÓTESIS | C5: 6000 | D5: 0 | E5: 0 | F5: 0 | G5: 0
A6: Asesoría jurídica España: contratos, sociedad, propiedad intelectual | B6: HIPÓTESIS | C6: 6000 | D6: 2500 | E6: 2500 | F6: 2500 | G6: 2500
A7: Habilitación CMT, notificación EU-CEG, gestión regulatoria | B7: HIPÓTESIS | C7: 3000 | D7: 800 | E7: 800 | F7: 1500 | G7: 800
A8: Gestoría, contabilidad, auditoría ligera | B8: HIPÓTESIS | C8: 1800 | D8: 3600 | E8: 3600 | F8: 3800 | G8: 4000
A9: Seguros (RC producto, mercancía en almacén) | B9: HIPÓTESIS | C9: 600 | D9: 1500 | E9: 1500 | F9: 1600 | G9: 1700
A10: Almacén climatizado / depósito (3PL) | B10: HIPÓTESIS | C10: 0 | D10: 1800 | E10: 2400 | F10: 3000 | G10: 3600
A11: Viajes a Cuba (negociación, control de calidad) | B11: HIPÓTESIS | C11: 5000 | D11: 3000 | E11: 3000 | F11: 3000 | G11: 3000
A12: Desarrollo comercial B2B (ferias profesionales, logística de muestras) | B12: HIPÓTESIS | C12: 1000 | D12: 6000 | E12: 5000 | F12: 5000 | G12: 5000
A13: Software, trazabilidad, registros | B13: HIPÓTESIS | C13: 500 | D13: 1200 | E13: 1200 | F13: 1200 | G13: 1200
A14: Renovaciones y vigilancia de marcas | B14: HIPÓTESIS | C14: 0 | D14: 300 | E14: 300 | F14: 300 | G14: 300
A15: Remuneración del promotor (no incluida) | B15: HIPÓTESIS | C15: 0 | D15: 0 | E15: 0 | F15: 0 | G15: 0
A16: Imprevistos (% sobre el subtotal) | B16: 0.1 | C16: =SUM(C5:C15)*$B$16 -> 2390 | D16: =SUM(D5:D15)*$B$16 -> 2070 | E16: =SUM(E5:E15)*$B$16 -> 2030 | F16: =SUM(F5:F15)*$B$16 -> 2190 | G16: =SUM(G5:G15)*$B$16 -> 2210
A17: TOTAL GASTOS FIJOS (base) | C17: =SUM(C5:C16) -> 26290 | D17: =SUM(D5:D16) -> 22770 | E17: =SUM(E5:E16) -> 22330 | F17: =SUM(F5:F16) -> 24090 | G17: =SUM(G5:G16) -> 24310
A19: CAPEX intangible (amortizable)
A20: Registro de marcas: EUIPO clase 34 + Cuba (OCPI vía agente) + vigilancia | B20: PROBABLE | C20: 4000 | D20: 0 | E20: 0 | F20: 0 | G20: 0
A21: Diseño de identidad, artes finales, troqueles y planchas | B21: HIPÓTESIS | C21: 9000 | D21: 0 | E21: 3000 | F21: 0 | G21: 0
A22: TOTAL CAPEX | C22: =SUM(C20:C21) -> 13000 | D22: =SUM(D20:D21) -> 0 | E22: =SUM(E20:E21) -> 3000 | F22: =SUM(F20:F21) -> 0 | G22: =SUM(G20:G21) -> 0

Sheet Working Capital
A1: Capital circulante y desajuste temporal de caja
A2: Parte 1: saldos anuales. Parte 2: ciclo de caja mensual de un pedido (anticipo a Cuba → producción → transporte → frontera → ventas → cobro).
A3: ="Escenario: "&Assumptions!$D$4 -> Escenario: Base
A5: Concepto | B5: 2027 | C5: 2028 | D5: 2029 | E5: 2030 | F5: 2031
A6: Existencias | B6: =INDEX(Engine!$C$57:$Y$57,1,(Assumptions!$C$4-1)*6+1) -> 10089.218 | C6: =INDEX(Engine!$C$57:$Y$57,1,(Assumptions!$C$4-1)*6+2) -> 17656.131 | D6: =INDEX(Engine!$C$57:$Y$57,1,(Assumptions!$C$4-1)*6+3) -> 25223.044 | E6: =INDEX(Engine!$C$57:$Y$57,1,(Assumptions!$C$4-1)*6+4) -> 32789.957 | F6: =INDEX(Engine!$C$57:$Y$57,1,(Assumptions!$C$4-1)*6+5) -> 32789.957
A7: IEE anticipado sobre existencias | B7: =INDEX(Engine!$C$59:$Y$59,1,(Assumptions!$C$4-1)*6+1) -> 3792 | C7: =INDEX(Engine!$C$59:$Y$59,1,(Assumptions!$C$4-1)*6+2) -> 6636 | D7: =INDEX(Engine!$C$59:$Y$59,1,(Assumptions!$C$4-1)*6+3) -> 9480 | E7: =INDEX(Engine!$C$59:$Y$59,1,(Assumptions!$C$4-1)*6+4) -> 12324 | F7: =INDEX(Engine!$C$59:$Y$59,1,(Assumptions!$C$4-1)*6+5) -> 12324
A8: Anticipos a fábrica | B8: =INDEX(Engine!$C$61:$Y$61,1,(Assumptions!$C$4-1)*6+1) -> 4258.3585 | C8: =INDEX(Engine!$C$61:$Y$61,1,(Assumptions!$C$4-1)*6+2) -> 6618.058 | D8: =INDEX(Engine!$C$61:$Y$61,1,(Assumptions!$C$4-1)*6+3) -> 8977.7575 | E8: =INDEX(Engine!$C$61:$Y$61,1,(Assumptions!$C$4-1)*6+4) -> 10225.365 | F8: =INDEX(Engine!$C$61:$Y$61,1,(Assumptions!$C$4-1)*6+5) -> 10225.365
A9: Clientes | B9: =INDEX(Engine!$C$60:$Y$60,1,(Assumptions!$C$4-1)*6+1) -> 0 | C9: =INDEX(Engine!$C$60:$Y$60,1,(Assumptions!$C$4-1)*6+2) -> 4915.3315 | D9: =INDEX(Engine!$C$60:$Y$60,1,(Assumptions!$C$4-1)*6+3) -> 8601.8301 | E9: =INDEX(Engine!$C$60:$Y$60,1,(Assumptions!$C$4-1)*6+4) -> 12288.329 | F9: =INDEX(Engine!$C$60:$Y$60,1,(Assumptions!$C$4-1)*6+5) -> 15974.827
A10: Hacienda deudora IVA | B10: =INDEX(Engine!$C$63:$Y$63,1,(Assumptions!$C$4-1)*6+1) -> 708.81392 | C10: =INDEX(Engine!$C$63:$Y$63,1,(Assumptions!$C$4-1)*6+2) -> 2035.6113 | D10: =INDEX(Engine!$C$63:$Y$63,1,(Assumptions!$C$4-1)*6+3) -> 3163.6119 | E10: =INDEX(Engine!$C$63:$Y$63,1,(Assumptions!$C$4-1)*6+4) -> 4291.6126 | F10: =INDEX(Engine!$C$63:$Y$63,1,(Assumptions!$C$4-1)*6+5) -> 4888.0027
A11: (-) Proveedores | B11: =INDEX(Engine!$C$64:$Y$64,1,(Assumptions!$C$4-1)*6+1) -> 2160.8219 | C11: =INDEX(Engine!$C$64:$Y$64,1,(Assumptions!$C$4-1)*6+2) -> 1871.5068 | D11: =INDEX(Engine!$C$64:$Y$64,1,(Assumptions!$C$4-1)*6+3) -> 1835.3425 | E11: =INDEX(Engine!$C$64:$Y$64,1,(Assumptions!$C$4-1)*6+4) -> 1980 | F11: =INDEX(Engine!$C$64:$Y$64,1,(Assumptions!$C$4-1)*6+5) -> 1998.0822
A12: (-) Hacienda acreedora IVA | B12: =INDEX(Engine!$C$66:$Y$66,1,(Assumptions!$C$4-1)*6+1) -> 0 | C12: =INDEX(Engine!$C$66:$Y$66,1,(Assumptions!$C$4-1)*6+2) -> 1729.8446 | D12: =INDEX(Engine!$C$66:$Y$66,1,(Assumptions!$C$4-1)*6+3) -> 3027.2281 | E12: =INDEX(Engine!$C$66:$Y$66,1,(Assumptions!$C$4-1)*6+4) -> 4324.6116 | F12: =INDEX(Engine!$C$66:$Y$66,1,(Assumptions!$C$4-1)*6+5) -> 5621.995
A13: CAPITAL CIRCULANTE NETO | B13: =INDEX(Engine!$C$67:$Y$67,1,(Assumptions!$C$4-1)*6+1) -> 16687.568 | C13: =INDEX(Engine!$C$67:$Y$67,1,(Assumptions!$C$4-1)*6+2) -> 34259.78 | D13: =INDEX(Engine!$C$67:$Y$67,1,(Assumptions!$C$4-1)*6+3) -> 50583.673 | E13: =INDEX(Engine!$C$67:$Y$67,1,(Assumptions!$C$4-1)*6+4) -> 65614.652 | F13: =INDEX(Engine!$C$67:$Y$67,1,(Assumptions!$C$4-1)*6+5) -> 68582.075
A14: Variación | B14: =INDEX(Engine!$C$68:$Y$68,1,(Assumptions!$C$4-1)*6+1) -> 16687.568 | C14: =INDEX(Engine!$C$68:$Y$68,1,(Assumptions!$C$4-1)*6+2) -> 17572.212 | D14: =INDEX(Engine!$C$68:$Y$68,1,(Assumptions!$C$4-1)*6+3) -> 16323.893 | E14: =INDEX(Engine!$C$68:$Y$68,1,(Assumptions!$C$4-1)*6+4) -> 15030.979 | F14: =INDEX(Engine!$C$68:$Y$68,1,(Assumptions!$C$4-1)*6+5) -> 2967.4232
A18: Parte 2 — Ciclo de caja de un pedido (meses desde el pedido)
A19: Unidades del pedido | B19: 3000
A20: Meses de venta del lote tras llegada (incl. 1 mes de publicación de PVP en BOE) | B20: 12
A21: Incluir gastos fijos mensuales (1=sí) | B21: 1
A22: Plazo pedido→llegada (meses, escenario) | B22: =Assumptions!$G$48 -> 5
A23: Retraso de cobro (meses) = DSO/30 | B23: =ROUND(Assumptions!$C$24/30,0) -> 2
A25: Mes | B25: 0 | C25: 1 | D25: 2 | E25: 3 | F25: 4 | G25: 5 | H25: 6 | I25: 7 | J25: 8 | K25: 9 | L25: 10 | M25: 11 | N25: 12 | O25: 13 | P25: 14 | Q25: 15 | R25: 16 | S25: 17 | T25: 18 | U25: 19 | V25: 20 | W25: 21 | X25: 22 | Y25: 23 | Z25: 24
A26: Anticipo a fábrica | B26: =IF(B$25=0,-Assumptions!$C$23*$B$19*(INDEX(Engine!$C$20:$Y$20,1,(Assumptions!$C$4-1)*6+2)+INDEX(Engine!$C$21:$Y$21,1,(Assumptions!$C$4-1)*6+2)+Assumptions!$G$42),0) -> -10676.087 | C26: =IF(C$25=0,-Assumptions!$C$23*$B$19*(INDEX(Engine!$C$20:$Y$20,1,(Assumptions!$C$4-1)*6+2)+INDEX(Engine!$C$21:$Y$21,1,(Assumptions!$C$4-1)*6+2)+Assumptions!$G$42),0) -> 0 | D26: =IF(D$25=0,-Assumptions!$C$23*$B$19*(INDEX(Engine!$C$20:$Y$20,1,(Assumptions!$C$4-1)*6+2)+INDEX(Engine!$C$21:$Y$21,1,(Assumptions!$C$4-1)*6+2)+Assumptions!$G$42),0) -> 0 | E26: =IF(E$25=0,-Assumptions!$C$23*$B$19*(INDEX(Engine!$C$20:$Y$20,1,(Assumptions!$C$4-1)*6+2)+INDEX(Engine!$C$21:$Y$21,1,(Assumptions!$C$4-1)*6+2)+Assumptions!$G$42),0) -> 0 | F26: =IF(F$25=0,-Assumptions!$C$23*$B$19*(INDEX(Engine!$C$20:$Y$20,1,(Assumptions!$C$4-1)*6+2)+INDEX(Engine!$C$21:$Y$21,1,(Assumptions!$C$4-1)*6+2)+Assumptions!$G$42),0) -> 0 | G26: =IF(G$25=0,-Assumptions!$C$23*$B$19*(INDEX(Engine!$C$20:$Y$20,1,(Assumptions!$C$4-1)*6+2)+INDEX(Engine!$C$21:$Y$21,1,(Assumptions!$C$4-1)*6+2)+Assumptions!$G$42),0) -> 0 | H26: =IF(H$25=0,-Assumptions!$C$23*$B$19*(INDEX(Engine!$C$20:$Y$20,1,(Assumptions!$C$4-1)*6+2)+INDEX(Engine!$C$21:$Y$21,1,(Assumptions!$C$4-1)*6+2)+Assumptions!$G$42),0) -> 0 | I26: =IF(I$25=0,-Assumptions!$C$23*$B$19*(INDEX(Engine!$C$20:$Y$20,1,(Assumptions!$C$4-1)*6+2)+INDEX(Engine!$C$21:$Y$21,1,(Assumptions!$C$4-1)*6+2)+Assumptions!$G$42),0) -> 0 | ... Z26: =IF(Z$25=0,-Assumptions!$C$23*$B$19*(INDEX(Engine!$C$20:$Y$20,1,(Assumptions!$C$4-1)*6+2)+INDEX(Engine!$C$21:$Y$21,1,(Assumptions!$C$4-1)*6+2)+Assumptions!$G$42),0) -> 0
A27: Saldo a fábrica antes de embarque | B27: =IF(B$25=$B$22-1,-(1-Assumptions!$C$23)*$B$19*(INDEX(Engine!$C$20:$Y$20,1,(Assumptions!$C$4-1)*6+2)+INDEX(Engine!$C$21:$Y$21,1,(Assumptions!$C$4-1)*6+2)+Assumptions!$G$42),0) -> 0 | C27: =IF(C$25=$B$22-1,-(1-Assumptions!$C$23)*$B$19*(INDEX(Engine!$C$20:$Y$20,1,(Assumptions!$C$4-1)*6+2)+INDEX(Engine!$C$21:$Y$21,1,(Assumptions!$C$4-1)*6+2)+Assumptions!$G$42),0) -> 0 | D27: =IF(D$25=$B$22-1,-(1-Assumptions!$C$23)*$B$19*(INDEX(Engine!$C$20:$Y$20,1,(Assumptions!$C$4-1)*6+2)+INDEX(Engine!$C$21:$Y$21,1,(Assumptions!$C$4-1)*6+2)+Assumptions!$G$42),0) -> 0 | E27: =IF(E$25=$B$22-1,-(1-Assumptions!$C$23)*$B$19*(INDEX(Engine!$C$20:$Y$20,1,(Assumptions!$C$4-1)*6+2)+INDEX(Engine!$C$21:$Y$21,1,(Assumptions!$C$4-1)*6+2)+Assumptions!$G$42),0) -> 0 | F27: =IF(F$25=$B$22-1,-(1-Assumptions!$C$23)*$B$19*(INDEX(Engine!$C$20:$Y$20,1,(Assumptions!$C$4-1)*6+2)+INDEX(Engine!$C$21:$Y$21,1,(Assumptions!$C$4-1)*6+2)+Assumptions!$G$42),0) -> -10676.087 | G27: =IF(G$25=$B$22-1,-(1-Assumptions!$C$23)*$B$19*(INDEX(Engine!$C$20:$Y$20,1,(Assumptions!$C$4-1)*6+2)+INDEX(Engine!$C$21:$Y$21,1,(Assumptions!$C$4-1)*6+2)+Assumptions!$G$42),0) -> 0 | H27: =IF(H$25=$B$22-1,-(1-Assumptions!$C$23)*$B$19*(INDEX(Engine!$C$20:$Y$20,1,(Assumptions!$C$4-1)*6+2)+INDEX(Engine!$C$21:$Y$21,1,(Assumptions!$C$4-1)*6+2)+Assumptions!$G$42),0) -> 0 | I27: =IF(I$25=$B$22-1,-(1-Assumptions!$C$23)*$B$19*(INDEX(Engine!$C$20:$Y$20,1,(Assumptions!$C$4-1)*6+2)+INDEX(Engine!$C$21:$Y$21,1,(Assumptions!$C$4-1)*6+2)+Assumptions!$G$42),0) -> 0 | ... Z27: =IF(Z$25=$B$22-1,-(1-Assumptions!$C$23)*$B$19*(INDEX(Engine!$C$20:$Y$20,1,(Assumptions!$C$4-1)*6+2)+INDEX(Engine!$C$21:$Y$21,1,(Assumptions!$C$4-1)*6+2)+Assumptions!$G$42),0) -> 0
A28: Flete y seguro | B28: =IF(B$25=$B$22-1,-$B$19*(INDEX(Engine!$C$22:$Y$22,1,(Assumptions!$C$4-1)*6+2)-(INDEX(Engine!$C$20:$Y$20,1,(Assumptions!$C$4-1)*6+2)+INDEX(Engine!$C$21:$Y$21,1,(Assumptions!$C$4-1)*6+2)+Assumptions!$G$42)),0) -> 0 | C28: =IF(C$25=$B$22-1,-$B$19*(INDEX(Engine!$C$22:$Y$22,1,(Assumptions!$C$4-1)*6+2)-(INDEX(Engine!$C$20:$Y$20,1,(Assumptions!$C$4-1)*6+2)+INDEX(Engine!$C$21:$Y$21,1,(Assumptions!$C$4-1)*6+2)+Assumptions!$G$42)),0) -> 0 | D28: =IF(D$25=$B$22-1,-$B$19*(INDEX(Engine!$C$22:$Y$22,1,(Assumptions!$C$4-1)*6+2)-(INDEX(Engine!$C$20:$Y$20,1,(Assumptions!$C$4-1)*6+2)+INDEX(Engine!$C$21:$Y$21,1,(Assumptions!$C$4-1)*6+2)+Assumptions!$G$42)),0) -> 0 | E28: =IF(E$25=$B$22-1,-$B$19*(INDEX(Engine!$C$22:$Y$22,1,(Assumptions!$C$4-1)*6+2)-(INDEX(Engine!$C$20:$Y$20,1,(Assumptions!$C$4-1)*6+2)+INDEX(Engine!$C$21:$Y$21,1,(Assumptions!$C$4-1)*6+2)+Assumptions!$G$42)),0) -> 0 | F28: =IF(F$25=$B$22-1,-$B$19*(INDEX(Engine!$C$22:$Y$22,1,(Assumptions!$C$4-1)*6+2)-(INDEX(Engine!$C$20:$Y$20,1,(Assumptions!$C$4-1)*6+2)+INDEX(Engine!$C$21:$Y$21,1,(Assumptions!$C$4-1)*6+2)+Assumptions!$G$42)),0) -> -1765.0109 | G28: =IF(G$25=$B$22-1,-$B$19*(INDEX(Engine!$C$22:$Y$22,1,(Assumptions!$C$4-1)*6+2)-(INDEX(Engine!$C$20:$Y$20,1,(Assumptions!$C$4-1)*6+2)+INDEX(Engine!$C$21:$Y$21,1,(Assumptions!$C$4-1)*6+2)+Assumptions!$G$42)),0) -> 0 | H28: =IF(H$25=$B$22-1,-$B$19*(INDEX(Engine!$C$22:$Y$22,1,(Assumptions!$C$4-1)*6+2)-(INDEX(Engine!$C$20:$Y$20,1,(Assumptions!$C$4-1)*6+2)+INDEX(Engine!$C$21:$Y$21,1,(Assumptions!$C$4-1)*6+2)+Assumptions!$G$42)),0) -> 0 | I28: =IF(I$25=$B$22-1,-$B$19*(INDEX(Engine!$C$22:$Y$22,1,(Assumptions!$C$4-1)*6+2)-(INDEX(Engine!$C$20:$Y$20,1,(Assumptions!$C$4-1)*6+2)+INDEX(Engine!$C$21:$Y$21,1,(Assumptions!$C$4-1)*6+2)+Assumptions!$G$42)),0) -> 0 | ... Z28: =IF(Z$25=$B$22-1,-$B$19*(INDEX(Engine!$C$22:$Y$22,1,(Assumptions!$C$4-1)*6+2)-(INDEX(Engine!$C$20:$Y$20,1,(Assumptions!$C$4-1)*6+2)+INDEX(Engine!$C$21:$Y$21,1,(Assumptions!$C$4-1)*6+2)+Assumptions!$G$42)),0) -> 0
A29: Arancel + despacho en frontera | B29: =IF(B$25=$B$22,-($B$19*INDEX(Engine!$C$23:$Y$23,1,(Assumptions!$C$4-1)*6+2)+Assumptions!$C$17+$B$19*(Assumptions!$C$16+Assumptions!$G$44)),0) -> 0 | C29: =IF(C$25=$B$22,-($B$19*INDEX(Engine!$C$23:$Y$23,1,(Assumptions!$C$4-1)*6+2)+Assumptions!$C$17+$B$19*(Assumptions!$C$16+Assumptions!$G$44)),0) -> 0 | D29: =IF(D$25=$B$22,-($B$19*INDEX(Engine!$C$23:$Y$23,1,(Assumptions!$C$4-1)*6+2)+Assumptions!$C$17+$B$19*(Assumptions!$C$16+Assumptions!$G$44)),0) -> 0 | E29: =IF(E$25=$B$22,-($B$19*INDEX(Engine!$C$23:$Y$23,1,(Assumptions!$C$4-1)*6+2)+Assumptions!$C$17+$B$19*(Assumptions!$C$16+Assumptions!$G$44)),0) -> 0 | F29: =IF(F$25=$B$22,-($B$19*INDEX(Engine!$C$23:$Y$23,1,(Assumptions!$C$4-1)*6+2)+Assumptions!$C$17+$B$19*(Assumptions!$C$16+Assumptions!$G$44)),0) -> 0 | G29: =IF(G$25=$B$22,-($B$19*INDEX(Engine!$C$23:$Y$23,1,(Assumptions!$C$4-1)*6+2)+Assumptions!$C$17+$B$19*(Assumptions!$C$16+Assumptions!$G$44)),0) -> -7600.468 | H29: =IF(H$25=$B$22,-($B$19*INDEX(Engine!$C$23:$Y$23,1,(Assumptions!$C$4-1)*6+2)+Assumptions!$C$17+$B$19*(Assumptions!$C$16+Assumptions!$G$44)),0) -> 0 | I29: =IF(I$25=$B$22,-($B$19*INDEX(Engine!$C$23:$Y$23,1,(Assumptions!$C$4-1)*6+2)+Assumptions!$C$17+$B$19*(Assumptions!$C$16+Assumptions!$G$44)),0) -> 0 | ... Z29: =IF(Z$25=$B$22,-($B$19*INDEX(Engine!$C$23:$Y$23,1,(Assumptions!$C$4-1)*6+2)+Assumptions!$C$17+$B$19*(Assumptions!$C$16+Assumptions!$G$44)),0) -> 0
A30: IEE (en frontera si se paga al importar; si no, al vender) | B30: =IF(Assumptions!$C$26=1,IF(B$25=$B$22,-$B$19*INDEX(Engine!$C$25:$Y$25,1,(Assumptions!$C$4-1)*6+2),0),IF(AND(B$25>$B$22,B$25<=$B$22+$B$20),-$B$19/$B$20*INDEX(Engine!$C$25:$Y$25,1,(Assumptions!$C$4-1)*6+2),0)) -> 0 | C30: =IF(Assumptions!$C$26=1,IF(C$25=$B$22,-$B$19*INDEX(Engine!$C$25:$Y$25,1,(Assumptions!$C$4-1)*6+2),0),IF(AND(C$25>$B$22,C$25<=$B$22+$B$20),-$B$19/$B$20*INDEX(Engine!$C$25:$Y$25,1,(Assumptions!$C$4-1)*6+2),0)) -> 0 | D30: =IF(Assumptions!$C$26=1,IF(D$25=$B$22,-$B$19*INDEX(Engine!$C$25:$Y$25,1,(Assumptions!$C$4-1)*6+2),0),IF(AND(D$25>$B$22,D$25<=$B$22+$B$20),-$B$19/$B$20*INDEX(Engine!$C$25:$Y$25,1,(Assumptions!$C$4-1)*6+2),0)) -> 0 | E30: =IF(Assumptions!$C$26=1,IF(E$25=$B$22,-$B$19*INDEX(Engine!$C$25:$Y$25,1,(Assumptions!$C$4-1)*6+2),0),IF(AND(E$25>$B$22,E$25<=$B$22+$B$20),-$B$19/$B$20*INDEX(Engine!$C$25:$Y$25,1,(Assumptions!$C$4-1)*6+2),0)) -> 0 | F30: =IF(Assumptions!$C$26=1,IF(F$25=$B$22,-$B$19*INDEX(Engine!$C$25:$Y$25,1,(Assumptions!$C$4-1)*6+2),0),IF(AND(F$25>$B$22,F$25<=$B$22+$B$20),-$B$19/$B$20*INDEX(Engine!$C$25:$Y$25,1,(Assumptions!$C$4-1)*6+2),0)) -> 0 | G30: =IF(Assumptions!$C$26=1,IF(G$25=$B$22,-$B$19*INDEX(Engine!$C$25:$Y$25,1,(Assumptions!$C$4-1)*6+2),0),IF(AND(G$25>$B$22,G$25<=$B$22+$B$20),-$B$19/$B$20*INDEX(Engine!$C$25:$Y$25,1,(Assumptions!$C$4-1)*6+2),0)) -> -11376 | H30: =IF(Assumptions!$C$26=1,IF(H$25=$B$22,-$B$19*INDEX(Engine!$C$25:$Y$25,1,(Assumptions!$C$4-1)*6+2),0),IF(AND(H$25>$B$22,H$25<=$B$22+$B$20),-$B$19/$B$20*INDEX(Engine!$C$25:$Y$25,1,(Assumptions!$C$4-1)*6+2),0)) -> 0 | I30: =IF(Assumptions!$C$26=1,IF(I$25=$B$22,-$B$19*INDEX(Engine!$C$25:$Y$25,1,(Assumptions!$C$4-1)*6+2),0),IF(AND(I$25>$B$22,I$25<=$B$22+$B$20),-$B$19/$B$20*INDEX(Engine!$C$25:$Y$25,1,(Assumptions!$C$4-1)*6+2),0)) -> 0 | ... Z30: =IF(Assumptions!$C$26=1,IF(Z$25=$B$22,-$B$19*INDEX(Engine!$C$25:$Y$25,1,(Assumptions!$C$4-1)*6+2),0),IF(AND(Z$25>$B$22,Z$25<=$B$22+$B$20),-$B$19/$B$20*INDEX(Engine!$C$25:$Y$25,1,(Assumptions!$C$4-1)*6+2),0)) -> 0
A31: IVA de importación pagado | B31: =IF(B$25=$B$22,-$B$19*(INDEX(Engine!$C$22:$Y$22,1,(Assumptions!$C$4-1)*6+2)+INDEX(Engine!$C$23:$Y$23,1,(Assumptions!$C$4-1)*6+2)+Assumptions!$C$26*INDEX(Engine!$C$25:$Y$25,1,(Assumptions!$C$4-1)*6+2))*Assumptions!$C$10,0) -> 0 | C31: =IF(C$25=$B$22,-$B$19*(INDEX(Engine!$C$22:$Y$22,1,(Assumptions!$C$4-1)*6+2)+INDEX(Engine!$C$23:$Y$23,1,(Assumptions!$C$4-1)*6+2)+Assumptions!$C$26*INDEX(Engine!$C$25:$Y$25,1,(Assumptions!$C$4-1)*6+2))*Assumptions!$C$10,0) -> 0 | D31: =IF(D$25=$B$22,-$B$19*(INDEX(Engine!$C$22:$Y$22,1,(Assumptions!$C$4-1)*6+2)+INDEX(Engine!$C$23:$Y$23,1,(Assumptions!$C$4-1)*6+2)+Assumptions!$C$26*INDEX(Engine!$C$25:$Y$25,1,(Assumptions!$C$4-1)*6+2))*Assumptions!$C$10,0) -> 0 | E31: =IF(E$25=$B$22,-$B$19*(INDEX(Engine!$C$22:$Y$22,1,(Assumptions!$C$4-1)*6+2)+INDEX(Engine!$C$23:$Y$23,1,(Assumptions!$C$4-1)*6+2)+Assumptions!$C$26*INDEX(Engine!$C$25:$Y$25,1,(Assumptions!$C$4-1)*6+2))*Assumptions!$C$10,0) -> 0 | F31: =IF(F$25=$B$22,-$B$19*(INDEX(Engine!$C$22:$Y$22,1,(Assumptions!$C$4-1)*6+2)+INDEX(Engine!$C$23:$Y$23,1,(Assumptions!$C$4-1)*6+2)+Assumptions!$C$26*INDEX(Engine!$C$25:$Y$25,1,(Assumptions!$C$4-1)*6+2))*Assumptions!$C$10,0) -> 0 | G31: =IF(G$25=$B$22,-$B$19*(INDEX(Engine!$C$22:$Y$22,1,(Assumptions!$C$4-1)*6+2)+INDEX(Engine!$C$23:$Y$23,1,(Assumptions!$C$4-1)*6+2)+Assumptions!$C$26*INDEX(Engine!$C$25:$Y$25,1,(Assumptions!$C$4-1)*6+2))*Assumptions!$C$10,0) -> -8505.7671 | H31: =IF(H$25=$B$22,-$B$19*(INDEX(Engine!$C$22:$Y$22,1,(Assumptions!$C$4-1)*6+2)+INDEX(Engine!$C$23:$Y$23,1,(Assumptions!$C$4-1)*6+2)+Assumptions!$C$26*INDEX(Engine!$C$25:$Y$25,1,(Assumptions!$C$4-1)*6+2))*Assumptions!$C$10,0) -> 0 | I31: =IF(I$25=$B$22,-$B$19*(INDEX(Engine!$C$22:$Y$22,1,(Assumptions!$C$4-1)*6+2)+INDEX(Engine!$C$23:$Y$23,1,(Assumptions!$C$4-1)*6+2)+Assumptions!$C$26*INDEX(Engine!$C$25:$Y$25,1,(Assumptions!$C$4-1)*6+2))*Assumptions!$C$10,0) -> 0 | ... Z31: =IF(Z$25=$B$22,-$B$19*(INDEX(Engine!$C$22:$Y$22,1,(Assumptions!$C$4-1)*6+2)+INDEX(Engine!$C$23:$Y$23,1,(Assumptions!$C$4-1)*6+2)+Assumptions!$C$26*INDEX(Engine!$C$25:$Y$25,1,(Assumptions!$C$4-1)*6+2))*Assumptions!$C$10,0) -> 0
A32: Devolución/compensación IVA importación (+3 meses) | B32: =IF(B$25=$B$22+3,$B$19*(INDEX(Engine!$C$22:$Y$22,1,(Assumptions!$C$4-1)*6+2)+INDEX(Engine!$C$23:$Y$23,1,(Assumptions!$C$4-1)*6+2)+Assumptions!$C$26*INDEX(Engine!$C$25:$Y$25,1,(Assumptions!$C$4-1)*6+2))*Assumptions!$C$10,0) -> 0 | C32: =IF(C$25=$B$22+3,$B$19*(INDEX(Engine!$C$22:$Y$22,1,(Assumptions!$C$4-1)*6+2)+INDEX(Engine!$C$23:$Y$23,1,(Assumptions!$C$4-1)*6+2)+Assumptions!$C$26*INDEX(Engine!$C$25:$Y$25,1,(Assumptions!$C$4-1)*6+2))*Assumptions!$C$10,0) -> 0 | D32: =IF(D$25=$B$22+3,$B$19*(INDEX(Engine!$C$22:$Y$22,1,(Assumptions!$C$4-1)*6+2)+INDEX(Engine!$C$23:$Y$23,1,(Assumptions!$C$4-1)*6+2)+Assumptions!$C$26*INDEX(Engine!$C$25:$Y$25,1,(Assumptions!$C$4-1)*6+2))*Assumptions!$C$10,0) -> 0 | E32: =IF(E$25=$B$22+3,$B$19*(INDEX(Engine!$C$22:$Y$22,1,(Assumptions!$C$4-1)*6+2)+INDEX(Engine!$C$23:$Y$23,1,(Assumptions!$C$4-1)*6+2)+Assumptions!$C$26*INDEX(Engine!$C$25:$Y$25,1,(Assumptions!$C$4-1)*6+2))*Assumptions!$C$10,0) -> 0 | F32: =IF(F$25=$B$22+3,$B$19*(INDEX(Engine!$C$22:$Y$22,1,(Assumptions!$C$4-1)*6+2)+INDEX(Engine!$C$23:$Y$23,1,(Assumptions!$C$4-1)*6+2)+Assumptions!$C$26*INDEX(Engine!$C$25:$Y$25,1,(Assumptions!$C$4-1)*6+2))*Assumptions!$C$10,0) -> 0 | G32: =IF(G$25=$B$22+3,$B$19*(INDEX(Engine!$C$22:$Y$22,1,(Assumptions!$C$4-1)*6+2)+INDEX(Engine!$C$23:$Y$23,1,(Assumptions!$C$4-1)*6+2)+Assumptions!$C$26*INDEX(Engine!$C$25:$Y$25,1,(Assumptions!$C$4-1)*6+2))*Assumptions!$C$10,0) -> 0 | H32: =IF(H$25=$B$22+3,$B$19*(INDEX(Engine!$C$22:$Y$22,1,(Assumptions!$C$4-1)*6+2)+INDEX(Engine!$C$23:$Y$23,1,(Assumptions!$C$4-1)*6+2)+Assumptions!$C$26*INDEX(Engine!$C$25:$Y$25,1,(Assumptions!$C$4-1)*6+2))*Assumptions!$C$10,0) -> 0 | I32: =IF(I$25=$B$22+3,$B$19*(INDEX(Engine!$C$22:$Y$22,1,(Assumptions!$C$4-1)*6+2)+INDEX(Engine!$C$23:$Y$23,1,(Assumptions!$C$4-1)*6+2)+Assumptions!$C$26*INDEX(Engine!$C$25:$Y$25,1,(Assumptions!$C$4-1)*6+2))*Assumptions!$C$10,0) -> 0 | ... Z32: =IF(Z$25=$B$22+3,$B$19*(INDEX(Engine!$C$22:$Y$22,1,(Assumptions!$C$4-1)*6+2)+INDEX(Engine!$C$23:$Y$23,1,(Assumptions!$C$4-1)*6+2)+Assumptions!$C$26*INDEX(Engine!$C$25:$Y$25,1,(Assumptions!$C$4-1)*6+2))*Assumptions!$C$10,0) -> 0
A33: Cobros del distribuidor (netos de IVA repercutido) | B33: =IF(AND(B$25>$B$22+1+$B$23,B$25<=$B$22+1+$B$23+$B$20-1),$B$19/$B$20/INDEX(Engine!$C$10:$Y$10,1,(Assumptions!$C$4-1)*6+2)*(INDEX(Engine!$C$33:$Y$33,1,(Assumptions!$C$4-1)*6+3)/MAX(1,INDEX(Engine!$C$14:$Y$14,1,(Assumptions!$C$4-1)*6+3))),0) -> 0 | C33: =IF(AND(C$25>$B$22+1+$B$23,C$25<=$B$22+1+$B$23+$B$20-1),$B$19/$B$20/INDEX(Engine!$C$10:$Y$10,1,(Assumptions!$C$4-1)*6+2)*(INDEX(Engine!$C$33:$Y$33,1,(Assumptions!$C$4-1)*6+3)/MAX(1,INDEX(Engine!$C$14:$Y$14,1,(Assumptions!$C$4-1)*6+3))),0) -> 0 | D33: =IF(AND(D$25>$B$22+1+$B$23,D$25<=$B$22+1+$B$23+$B$20-1),$B$19/$B$20/INDEX(Engine!$C$10:$Y$10,1,(Assumptions!$C$4-1)*6+2)*(INDEX(Engine!$C$33:$Y$33,1,(Assumptions!$C$4-1)*6+3)/MAX(1,INDEX(Engine!$C$14:$Y$14,1,(Assumptions!$C$4-1)*6+3))),0) -> 0 | E33: =IF(AND(E$25>$B$22+1+$B$23,E$25<=$B$22+1+$B$23+$B$20-1),$B$19/$B$20/INDEX(Engine!$C$10:$Y$10,1,(Assumptions!$C$4-1)*6+2)*(INDEX(Engine!$C$33:$Y$33,1,(Assumptions!$C$4-1)*6+3)/MAX(1,INDEX(Engine!$C$14:$Y$14,1,(Assumptions!$C$4-1)*6+3))),0) -> 0 | F33: =IF(AND(F$25>$B$22+1+$B$23,F$25<=$B$22+1+$B$23+$B$20-1),$B$19/$B$20/INDEX(Engine!$C$10:$Y$10,1,(Assumptions!$C$4-1)*6+2)*(INDEX(Engine!$C$33:$Y$33,1,(Assumptions!$C$4-1)*6+3)/MAX(1,INDEX(Engine!$C$14:$Y$14,1,(Assumptions!$C$4-1)*6+3))),0) -> 0 | G33: =IF(AND(G$25>$B$22+1+$B$23,G$25<=$B$22+1+$B$23+$B$20-1),$B$19/$B$20/INDEX(Engine!$C$10:$Y$10,1,(Assumptions!$C$4-1)*6+2)*(INDEX(Engine!$C$33:$Y$33,1,(Assumptions!$C$4-1)*6+3)/MAX(1,INDEX(Engine!$C$14:$Y$14,1,(Assumptions!$C$4-1)*6+3))),0) -> 0 | H33: =IF(AND(H$25>$B$22+1+$B$23,H$25<=$B$22+1+$B$23+$B$20-1),$B$19/$B$20/INDEX(Engine!$C$10:$Y$10,1,(Assumptions!$C$4-1)*6+2)*(INDEX(Engine!$C$33:$Y$33,1,(Assumptions!$C$4-1)*6+3)/MAX(1,INDEX(Engine!$C$14:$Y$14,1,(Assumptions!$C$4-1)*6+3))),0) -> 0 | I33: =IF(AND(I$25>$B$22+1+$B$23,I$25<=$B$22+1+$B$23+$B$20-1),$B$19/$B$20/INDEX(Engine!$C$10:$Y$10,1,(Assumptions!$C$4-1)*6+2)*(INDEX(Engine!$C$33:$Y$33,1,(Assumptions!$C$4-1)*6+3)/MAX(1,INDEX(Engine!$C$14:$Y$14,1,(Assumptions!$C$4-1)*6+3))),0) -> 0 | ... Z33: =IF(AND(Z$25>$B$22+1+$B$23,Z$25<=$B$22+1+$B$23+$B$20-1),$B$19/$B$20/INDEX(Engine!$C$10:$Y$10,1,(Assumptions!$C$4-1)*6+2)*(INDEX(Engine!$C$33:$Y$33,1,(Assumptions!$C$4-1)*6+3)/MAX(1,INDEX(Engine!$C$14:$Y$14,1,(Assumptions!$C$4-1)*6+3))),0) -> 0
A34: Gastos fijos mensuales | B34: =IF($B$21=1,-INDEX(Engine!$C$40:$Y$40,1,(Assumptions!$C$4-1)*6+2)/12,0) -> -1897.5 | C34: =IF($B$21=1,-INDEX(Engine!$C$40:$Y$40,1,(Assumptions!$C$4-1)*6+2)/12,0) -> -1897.5 | D34: =IF($B$21=1,-INDEX(Engine!$C$40:$Y$40,1,(Assumptions!$C$4-1)*6+2)/12,0) -> -1897.5 | E34: =IF($B$21=1,-INDEX(Engine!$C$40:$Y$40,1,(Assumptions!$C$4-1)*6+2)/12,0) -> -1897.5 | F34: =IF($B$21=1,-INDEX(Engine!$C$40:$Y$40,1,(Assumptions!$C$4-1)*6+2)/12,0) -> -1897.5 | G34: =IF($B$21=1,-INDEX(Engine!$C$40:$Y$40,1,(Assumptions!$C$4-1)*6+2)/12,0) -> -1897.5 | H34: =IF($B$21=1,-INDEX(Engine!$C$40:$Y$40,1,(Assumptions!$C$4-1)*6+2)/12,0) -> -1897.5 | I34: =IF($B$21=1,-INDEX(Engine!$C$40:$Y$40,1,(Assumptions!$C$4-1)*6+2)/12,0) -> -1897.5 | ... Z34: =IF($B$21=1,-INDEX(Engine!$C$40:$Y$40,1,(Assumptions!$C$4-1)*6+2)/12,0) -> -1897.5
A35: Flujo neto del mes | B35: =SUM(B26:B34) -> -12573.587 | C35: =SUM(C26:C34) -> -1897.5 | D35: =SUM(D26:D34) -> -1897.5 | E35: =SUM(E26:E34) -> -1897.5 | F35: =SUM(F26:F34) -> -14338.598 | G35: =SUM(G26:G34) -> -29379.735 | H35: =SUM(H26:H34) -> -1897.5 | I35: =SUM(I26:I34) -> -1897.5 | ... Z35: =SUM(Z26:Z34) -> -1897.5
A36: Caja acumulada del pedido | B36: =B35 -> -12573.587 | C36: =B36+C35 -> -14471.087 | D36: =C36+D35 -> -16368.587 | E36: =D36+E35 -> -18266.087 | F36: =E36+F35 -> -32604.685 | G36: =F36+G35 -> -61984.42 | H36: =G36+H35 -> -63881.92 | I36: =H36+I35 -> -65779.42 | J36: =I36+J35 -> -59171.153 | ... Z36: =Y36+Z35 -> -46827.537
A38: Necesidad máxima de caja del ciclo (−mínimo acumulado) | B38: =-MIN(0,MIN(B36:Z36)) -> 65779.42
A39: Mes en que se alcanza | B39: =MATCH(MIN(B36:Z36),B36:Z36,0)-1 -> 7
A40: Meses entre el primer pago a Cuba y el primer cobro | B40: =$B$22+2+$B$23 -> 9
A41: Nota: los cobros usan el ingreso neto unitario de 2029 del escenario; el ciclo ilustra el desajuste anticipo→cobro, no sustituye al modelo anual.

Sheet Profit & Loss
A1: Cuenta de resultados 2027–2031 (escenario seleccionado)
A2: € sin IVA. Los importes del consumidor y del canal se muestran para separar ingresos de marca, distribuidor y detallista.
A3: ="Escenario: "&Assumptions!$D$4 -> Escenario: Base
A5: Concepto | B5: 2027 | C5: 2028 | D5: 2029 | E5: 2030 | F5: 2031
A6: Unidades vendidas | B6: =INDEX(Engine!$C$14:$Y$14,1,(Assumptions!$C$4-1)*6+1) -> 0 | C6: =INDEX(Engine!$C$14:$Y$14,1,(Assumptions!$C$4-1)*6+2) -> 2000 | D6: =INDEX(Engine!$C$14:$Y$14,1,(Assumptions!$C$4-1)*6+3) -> 3500 | E6: =INDEX(Engine!$C$14:$Y$14,1,(Assumptions!$C$4-1)*6+4) -> 5000 | F6: =INDEX(Engine!$C$14:$Y$14,1,(Assumptions!$C$4-1)*6+5) -> 6500
A7: Ventas a PVP con IVA (gasto del consumidor, informativo) | B7: =INDEX(Engine!$C$29:$Y$29,1,(Assumptions!$C$4-1)*6+1) -> 0 | C7: =INDEX(Engine!$C$29:$Y$29,1,(Assumptions!$C$4-1)*6+2) -> 48000 | D7: =INDEX(Engine!$C$29:$Y$29,1,(Assumptions!$C$4-1)*6+3) -> 84000 | E7: =INDEX(Engine!$C$29:$Y$29,1,(Assumptions!$C$4-1)*6+4) -> 120000 | F7: =INDEX(Engine!$C$29:$Y$29,1,(Assumptions!$C$4-1)*6+5) -> 156000
A8: Ventas a PVP sin IVA | B8: =INDEX(Engine!$C$30:$Y$30,1,(Assumptions!$C$4-1)*6+1) -> 0 | C8: =INDEX(Engine!$C$30:$Y$30,1,(Assumptions!$C$4-1)*6+2) -> 39669.421 | D8: =INDEX(Engine!$C$30:$Y$30,1,(Assumptions!$C$4-1)*6+3) -> 69421.488 | E8: =INDEX(Engine!$C$30:$Y$30,1,(Assumptions!$C$4-1)*6+4) -> 99173.554 | F8: =INDEX(Engine!$C$30:$Y$30,1,(Assumptions!$C$4-1)*6+5) -> 128925.62
A9: (-) Margen del expendedor (ingreso del detallista) | B9: =INDEX(Engine!$C$31:$Y$31,1,(Assumptions!$C$4-1)*6+1) -> 0 | C9: =INDEX(Engine!$C$31:$Y$31,1,(Assumptions!$C$4-1)*6+2) -> 4320 | D9: =INDEX(Engine!$C$31:$Y$31,1,(Assumptions!$C$4-1)*6+3) -> 7560 | E9: =INDEX(Engine!$C$31:$Y$31,1,(Assumptions!$C$4-1)*6+4) -> 10800 | F9: =INDEX(Engine!$C$31:$Y$31,1,(Assumptions!$C$4-1)*6+5) -> 14040
A10: (-) Tarifa del distribuidor (ingreso del mayorista) | B10: =INDEX(Engine!$C$32:$Y$32,1,(Assumptions!$C$4-1)*6+1) -> 0 | C10: =INDEX(Engine!$C$32:$Y$32,1,(Assumptions!$C$4-1)*6+2) -> 2400 | D10: =INDEX(Engine!$C$32:$Y$32,1,(Assumptions!$C$4-1)*6+3) -> 4200 | E10: =INDEX(Engine!$C$32:$Y$32,1,(Assumptions!$C$4-1)*6+4) -> 6000 | F10: =INDEX(Engine!$C$32:$Y$32,1,(Assumptions!$C$4-1)*6+5) -> 7800
A11: INGRESOS DE LA MARCA (antes de IEE) | B11: =INDEX(Engine!$C$33:$Y$33,1,(Assumptions!$C$4-1)*6+1) -> 0 | C11: =INDEX(Engine!$C$33:$Y$33,1,(Assumptions!$C$4-1)*6+2) -> 32949.421 | D11: =INDEX(Engine!$C$33:$Y$33,1,(Assumptions!$C$4-1)*6+3) -> 57661.488 | E11: =INDEX(Engine!$C$33:$Y$33,1,(Assumptions!$C$4-1)*6+4) -> 82373.554 | F11: =INDEX(Engine!$C$33:$Y$33,1,(Assumptions!$C$4-1)*6+5) -> 107085.62
A12: (-) Impuesto especial | B12: =INDEX(Engine!$C$34:$Y$34,1,(Assumptions!$C$4-1)*6+1) -> 0 | C12: =INDEX(Engine!$C$34:$Y$34,1,(Assumptions!$C$4-1)*6+2) -> 8046.0767 | D12: =INDEX(Engine!$C$34:$Y$34,1,(Assumptions!$C$4-1)*6+3) -> 14080.634 | E12: =INDEX(Engine!$C$34:$Y$34,1,(Assumptions!$C$4-1)*6+4) -> 20115.192 | F12: =INDEX(Engine!$C$34:$Y$34,1,(Assumptions!$C$4-1)*6+5) -> 26149.749
A13: Ingresos netos de impuestos | B13: =INDEX(Engine!$C$35:$Y$35,1,(Assumptions!$C$4-1)*6+1) -> 0 | C13: =INDEX(Engine!$C$35:$Y$35,1,(Assumptions!$C$4-1)*6+2) -> 24903.345 | D13: =INDEX(Engine!$C$35:$Y$35,1,(Assumptions!$C$4-1)*6+3) -> 43580.853 | E13: =INDEX(Engine!$C$35:$Y$35,1,(Assumptions!$C$4-1)*6+4) -> 62258.362 | F13: =INDEX(Engine!$C$35:$Y$35,1,(Assumptions!$C$4-1)*6+5) -> 80935.871
A14: (-) Coste de ventas | B14: =INDEX(Engine!$C$36:$Y$36,1,(Assumptions!$C$4-1)*6+1) -> 0 | C14: =INDEX(Engine!$C$36:$Y$36,1,(Assumptions!$C$4-1)*6+2) -> 21407.864 | D14: =INDEX(Engine!$C$36:$Y$36,1,(Assumptions!$C$4-1)*6+3) -> 37463.761 | E14: =INDEX(Engine!$C$36:$Y$36,1,(Assumptions!$C$4-1)*6+4) -> 53519.659 | F14: =INDEX(Engine!$C$36:$Y$36,1,(Assumptions!$C$4-1)*6+5) -> 69575.557
A15: (-) Despachos aduaneros | B15: =INDEX(Engine!$C$37:$Y$37,1,(Assumptions!$C$4-1)*6+1) -> 900 | C15: =INDEX(Engine!$C$37:$Y$37,1,(Assumptions!$C$4-1)*6+2) -> 900 | D15: =INDEX(Engine!$C$37:$Y$37,1,(Assumptions!$C$4-1)*6+3) -> 900 | E15: =INDEX(Engine!$C$37:$Y$37,1,(Assumptions!$C$4-1)*6+4) -> 900 | F15: =INDEX(Engine!$C$37:$Y$37,1,(Assumptions!$C$4-1)*6+5) -> 900
A16: (-) Royalty de nombre a Arnaldo | B16: =INDEX(Engine!$C$38:$Y$38,1,(Assumptions!$C$4-1)*6+1) -> 0 | C16: =INDEX(Engine!$C$38:$Y$38,1,(Assumptions!$C$4-1)*6+2) -> 0 | D16: =INDEX(Engine!$C$38:$Y$38,1,(Assumptions!$C$4-1)*6+3) -> 0 | E16: =INDEX(Engine!$C$38:$Y$38,1,(Assumptions!$C$4-1)*6+4) -> 0 | F16: =INDEX(Engine!$C$38:$Y$38,1,(Assumptions!$C$4-1)*6+5) -> 0
A17: MARGEN BRUTO | B17: =INDEX(Engine!$C$39:$Y$39,1,(Assumptions!$C$4-1)*6+1) -> -900 | C17: =INDEX(Engine!$C$39:$Y$39,1,(Assumptions!$C$4-1)*6+2) -> 2595.4812 | D17: =INDEX(Engine!$C$39:$Y$39,1,(Assumptions!$C$4-1)*6+3) -> 5217.0921 | E17: =INDEX(Engine!$C$39:$Y$39,1,(Assumptions!$C$4-1)*6+4) -> 7838.703 | F17: =INDEX(Engine!$C$39:$Y$39,1,(Assumptions!$C$4-1)*6+5) -> 10460.314
A18: (-) Gastos fijos | B18: =INDEX(Engine!$C$40:$Y$40,1,(Assumptions!$C$4-1)*6+1) -> 26290 | C18: =INDEX(Engine!$C$40:$Y$40,1,(Assumptions!$C$4-1)*6+2) -> 22770 | D18: =INDEX(Engine!$C$40:$Y$40,1,(Assumptions!$C$4-1)*6+3) -> 22330 | E18: =INDEX(Engine!$C$40:$Y$40,1,(Assumptions!$C$4-1)*6+4) -> 24090 | F18: =INDEX(Engine!$C$40:$Y$40,1,(Assumptions!$C$4-1)*6+5) -> 24310
